[2024-11-23T02:21:31.164+0000] {logging_mixin.py:151} INFO - Changing /opt/***/logs/dag_id=model_training_pipeline/run_id=manual__2024-11-23T02:21:25.574434+00:00/task_id=train_model permission to 509
[2024-11-23T02:21:31.165+0000] {logging_mixin.py:151} INFO - Failed to change /opt/***/logs/dag_id=model_training_pipeline/run_id=manual__2024-11-23T02:21:25.574434+00:00/task_id=train_model permission to 509: [Errno 1] Operation not permitted: '/opt/***/logs/dag_id=model_training_pipeline/run_id=manual__2024-11-23T02:21:25.574434+00:00/task_id=train_model'
[2024-11-23T02:21:31.201+0000] {logging_mixin.py:151} INFO - Changing /opt/***/logs/dag_id=model_training_pipeline/run_id=manual__2024-11-23T02:21:25.574434+00:00/task_id=train_model permission to 509
[2024-11-23T02:21:31.202+0000] {logging_mixin.py:151} INFO - Failed to change /opt/***/logs/dag_id=model_training_pipeline/run_id=manual__2024-11-23T02:21:25.574434+00:00/task_id=train_model permission to 509: [Errno 1] Operation not permitted: '/opt/***/logs/dag_id=model_training_pipeline/run_id=manual__2024-11-23T02:21:25.574434+00:00/task_id=train_model'
[2024-11-23T02:21:31.233+0000] {taskinstance.py:1159} INFO - Dependencies all met for dep_context=non-requeueable deps ti=<TaskInstance: model_training_pipeline.train_model manual__2024-11-23T02:21:25.574434+00:00 [queued]>
[2024-11-23T02:21:31.248+0000] {taskinstance.py:1159} INFO - Dependencies all met for dep_context=requeueable deps ti=<TaskInstance: model_training_pipeline.train_model manual__2024-11-23T02:21:25.574434+00:00 [queued]>
[2024-11-23T02:21:31.249+0000] {taskinstance.py:1361} INFO - Starting attempt 1 of 2
[2024-11-23T02:21:31.267+0000] {taskinstance.py:1382} INFO - Executing <Task(PythonOperator): train_model> on 2024-11-23 02:21:25.574434+00:00
[2024-11-23T02:21:31.281+0000] {standard_task_runner.py:57} INFO - Started process 67892 to run task
[2024-11-23T02:21:31.285+0000] {standard_task_runner.py:84} INFO - Running: ['***', 'tasks', 'run', 'model_training_pipeline', 'train_model', 'manual__2024-11-23T02:21:25.574434+00:00', '--job-id', '358', '--raw', '--subdir', 'DAGS_FOLDER/model_training_pipeline_dag/model_training_dag.py', '--cfg-path', '/tmp/tmp4wofaoyd']
[2024-11-23T02:21:31.288+0000] {standard_task_runner.py:85} INFO - Job 358: Subtask train_model
[2024-11-23T02:21:31.367+0000] {logging_mixin.py:151} INFO - Changing /opt/***/logs/dag_id=model_training_pipeline/run_id=manual__2024-11-23T02:21:25.574434+00:00/task_id=train_model permission to 509
[2024-11-23T02:21:31.368+0000] {logging_mixin.py:151} INFO - Failed to change /opt/***/logs/dag_id=model_training_pipeline/run_id=manual__2024-11-23T02:21:25.574434+00:00/task_id=train_model permission to 509: [Errno 1] Operation not permitted: '/opt/***/logs/dag_id=model_training_pipeline/run_id=manual__2024-11-23T02:21:25.574434+00:00/task_id=train_model'
[2024-11-23T02:21:31.371+0000] {task_command.py:415} INFO - Running <TaskInstance: model_training_pipeline.train_model manual__2024-11-23T02:21:25.574434+00:00 [running]> on host 16801ac1f6e4
[2024-11-23T02:21:31.480+0000] {taskinstance.py:1660} INFO - Exporting env vars: AIRFLOW_CTX_DAG_OWNER='***' AIRFLOW_CTX_DAG_ID='model_training_pipeline' AIRFLOW_CTX_TASK_ID='train_model' AIRFLOW_CTX_EXECUTION_DATE='2024-11-23T02:21:25.574434+00:00' AIRFLOW_CTX_TRY_NUMBER='1' AIRFLOW_CTX_DAG_RUN_ID='manual__2024-11-23T02:21:25.574434+00:00'
[2024-11-23T02:25:21.948+0000] {logging_mixin.py:151} INFO - Data has been normalised
[2024-11-23T02:25:22.409+0000] {logging_mixin.py:151} WARNING - 2024/11/23 02:25:22 WARNING mlflow.utils.git_utils: Failed to import Git (the Git executable is probably not on your PATH), so Git SHA is not available. Error: Failed to initialize: Bad git executable.
The git executable must be specified in one of the following ways:
    - be included in your $PATH
    - be set via $GIT_PYTHON_GIT_EXECUTABLE
    - explicitly set via git.refresh(<full-path-to-git-executable>)

All git commands will error until this is rectified.

This initial message can be silenced or aggravated in the future by setting the
$GIT_PYTHON_REFRESH environment variable. Use one of the following values:
    - quiet|q|silence|s|silent|none|n|0: for no message or exception
    - warn|w|warning|log|l|1: for a warning message (logging level CRITICAL, displayed by default)
    - error|e|exception|raise|r|2: for a raised exception

Example:
    export GIT_PYTHON_REFRESH=quiet
[2024-11-23T02:25:22.566+0000] {logging_mixin.py:151} WARNING - 2024/11/23 02:25:22 INFO mlflow.tracking._tracking_service.client: üèÉ View run GRU_7_day_horizon_30_20241123 at: http://mlflow:5000/#/experiments/1/runs/755e9562b46549ed99d3dd063cc6f8cd.
[2024-11-23T02:25:22.566+0000] {logging_mixin.py:151} WARNING - 2024/11/23 02:25:22 INFO mlflow.tracking._tracking_service.client: üß™ View experiment at: http://mlflow:5000/#/experiments/1.
[2024-11-23T02:25:22.587+0000] {taskinstance.py:1943} ERROR - Task failed with exception
Traceback (most recent call last):
  File "/home/airflow/.local/lib/python3.8/site-packages/airflow/operators/python.py", line 192, in execute
    return_value = self.execute_callable()
  File "/home/airflow/.local/lib/python3.8/site-packages/airflow/operators/python.py", line 209, in execute_callable
    return self.python_callable(*self.op_args, **self.op_kwargs)
  File "/opt/airflow/dags/model_training_pipeline_dag/train_model.py", line 74, in train_model
    Model.train_model(x_train=X_train, y_train=y_train, x_test=X_test, y_test=y_test, time_steps=30, experiment_id=experiment_id, forecast_horizon=7, batch_size=128)
  File "/opt/airflow/dags/modelling/model.py", line 49, in train_model
    model.fit(train_gen, epochs=150, batch_size=batch_size, validation_data=test_gen, verbose=2,
  File "/home/airflow/.local/lib/python3.8/site-packages/keras/src/utils/traceback_utils.py", line 70, in error_handler
    raise e.with_traceback(filtered_tb) from None
  File "/home/airflow/.local/lib/python3.8/site-packages/tensorflow/python/framework/constant_op.py", line 98, in convert_to_eager_tensor
    return ops.EagerTensor(value, ctx.device_name, dtype)
ValueError: Failed to convert a NumPy array to a Tensor (Unsupported object type float).
[2024-11-23T02:25:22.602+0000] {taskinstance.py:1400} INFO - Marking task as UP_FOR_RETRY. dag_id=model_training_pipeline, task_id=train_model, execution_date=20241123T022125, start_date=20241123T022131, end_date=20241123T022522
[2024-11-23T02:25:22.616+0000] {standard_task_runner.py:104} ERROR - Failed to execute job 358 for task train_model (Failed to convert a NumPy array to a Tensor (Unsupported object type float).; 67892)
[2024-11-23T02:25:22.690+0000] {local_task_job_runner.py:228} INFO - Task exited with return code 1
[2024-11-23T02:25:22.706+0000] {taskinstance.py:2784} INFO - 0 downstream tasks scheduled from follow-on schedule check
