[2024-11-17T08:14:17.631+0000] {logging_mixin.py:151} INFO - Changing /opt/***/logs/dag_id=model_training_pipeline/run_id=manual__2024-11-17T08:14:07.995917+00:00/task_id=weather_variables_feature_engineering permission to 509
[2024-11-17T08:14:17.632+0000] {logging_mixin.py:151} INFO - Failed to change /opt/***/logs/dag_id=model_training_pipeline/run_id=manual__2024-11-17T08:14:07.995917+00:00/task_id=weather_variables_feature_engineering permission to 509: [Errno 1] Operation not permitted: '/opt/***/logs/dag_id=model_training_pipeline/run_id=manual__2024-11-17T08:14:07.995917+00:00/task_id=weather_variables_feature_engineering'
[2024-11-17T08:14:17.676+0000] {logging_mixin.py:151} INFO - Changing /opt/***/logs/dag_id=model_training_pipeline/run_id=manual__2024-11-17T08:14:07.995917+00:00/task_id=weather_variables_feature_engineering permission to 509
[2024-11-17T08:14:17.677+0000] {logging_mixin.py:151} INFO - Failed to change /opt/***/logs/dag_id=model_training_pipeline/run_id=manual__2024-11-17T08:14:07.995917+00:00/task_id=weather_variables_feature_engineering permission to 509: [Errno 1] Operation not permitted: '/opt/***/logs/dag_id=model_training_pipeline/run_id=manual__2024-11-17T08:14:07.995917+00:00/task_id=weather_variables_feature_engineering'
[2024-11-17T08:14:17.713+0000] {taskinstance.py:1159} INFO - Dependencies all met for dep_context=non-requeueable deps ti=<TaskInstance: model_training_pipeline.weather_variables_feature_engineering manual__2024-11-17T08:14:07.995917+00:00 [queued]>
[2024-11-17T08:14:17.728+0000] {taskinstance.py:1159} INFO - Dependencies all met for dep_context=requeueable deps ti=<TaskInstance: model_training_pipeline.weather_variables_feature_engineering manual__2024-11-17T08:14:07.995917+00:00 [queued]>
[2024-11-17T08:14:17.728+0000] {taskinstance.py:1361} INFO - Starting attempt 1 of 2
[2024-11-17T08:14:17.751+0000] {taskinstance.py:1382} INFO - Executing <Task(PythonOperator): weather_variables_feature_engineering> on 2024-11-17 08:14:07.995917+00:00
[2024-11-17T08:14:17.769+0000] {standard_task_runner.py:57} INFO - Started process 147080 to run task
[2024-11-17T08:14:17.773+0000] {standard_task_runner.py:84} INFO - Running: ['***', 'tasks', 'run', 'model_training_pipeline', 'weather_variables_feature_engineering', 'manual__2024-11-17T08:14:07.995917+00:00', '--job-id', '279', '--raw', '--subdir', 'DAGS_FOLDER/model_training_pipeline_dag/model_training_dag.py', '--cfg-path', '/tmp/tmpl6nr84dj']
[2024-11-17T08:14:17.778+0000] {standard_task_runner.py:85} INFO - Job 279: Subtask weather_variables_feature_engineering
[2024-11-17T08:14:17.862+0000] {logging_mixin.py:151} INFO - Changing /opt/***/logs/dag_id=model_training_pipeline/run_id=manual__2024-11-17T08:14:07.995917+00:00/task_id=weather_variables_feature_engineering permission to 509
[2024-11-17T08:14:17.863+0000] {logging_mixin.py:151} INFO - Failed to change /opt/***/logs/dag_id=model_training_pipeline/run_id=manual__2024-11-17T08:14:07.995917+00:00/task_id=weather_variables_feature_engineering permission to 509: [Errno 1] Operation not permitted: '/opt/***/logs/dag_id=model_training_pipeline/run_id=manual__2024-11-17T08:14:07.995917+00:00/task_id=weather_variables_feature_engineering'
[2024-11-17T08:14:17.865+0000] {task_command.py:415} INFO - Running <TaskInstance: model_training_pipeline.weather_variables_feature_engineering manual__2024-11-17T08:14:07.995917+00:00 [running]> on host 16801ac1f6e4
[2024-11-17T08:14:18.014+0000] {taskinstance.py:1660} INFO - Exporting env vars: AIRFLOW_CTX_DAG_OWNER='***' AIRFLOW_CTX_DAG_ID='model_training_pipeline' AIRFLOW_CTX_TASK_ID='weather_variables_feature_engineering' AIRFLOW_CTX_EXECUTION_DATE='2024-11-17T08:14:07.995917+00:00' AIRFLOW_CTX_TRY_NUMBER='1' AIRFLOW_CTX_DAG_RUN_ID='manual__2024-11-17T08:14:07.995917+00:00'
[2024-11-17T08:14:43.076+0000] {local_task_job_runner.py:294} WARNING - State of this instance has been externally set to None. Terminating instance.
[2024-11-17T08:14:43.082+0000] {process_utils.py:131} INFO - Sending 15 to group 147080. PIDs of all processes in the group: [147080]
[2024-11-17T08:14:43.083+0000] {process_utils.py:86} INFO - Sending the signal 15 to group 147080
[2024-11-17T08:14:43.084+0000] {taskinstance.py:1632} ERROR - Received SIGTERM. Terminating subprocesses.
[2024-11-17T08:14:43.109+0000] {taskinstance.py:1943} ERROR - Task failed with exception
Traceback (most recent call last):
  File "/home/airflow/.local/lib/python3.8/site-packages/airflow/operators/python.py", line 192, in execute
    return_value = self.execute_callable()
  File "/home/airflow/.local/lib/python3.8/site-packages/airflow/operators/python.py", line 209, in execute_callable
    return self.python_callable(*self.op_args, **self.op_kwargs)
  File "/opt/airflow/dags/model_training_pipeline_dag/weather_variables_feature_engineering.py", line 19, in weather_variables_feature_engineering
    curated_training_data_json = s3.get_data(folder='full_program/curated/training_data/', object_key=f'curated_training_data_{formatted_date}')
  File "/opt/airflow/dags/utils/aws.py", line 70, in get_data
    contents = response['Body'].read().decode('utf-8')
  File "/home/airflow/.local/lib/python3.8/site-packages/botocore/response.py", line 99, in read
    chunk = self._raw_stream.read(amt)
  File "/home/airflow/.local/lib/python3.8/site-packages/urllib3/response.py", line 567, in read
    data = self._fp_read(amt) if not fp_closed else b""
  File "/home/airflow/.local/lib/python3.8/site-packages/urllib3/response.py", line 533, in _fp_read
    return self._fp.read(amt) if amt is not None else self._fp.read()
  File "/usr/local/lib/python3.8/http/client.py", line 472, in read
    s = self._safe_read(self.length)
  File "/usr/local/lib/python3.8/http/client.py", line 613, in _safe_read
    data = self.fp.read(amt)
  File "/usr/local/lib/python3.8/socket.py", line 669, in readinto
    return self._sock.recv_into(b)
  File "/usr/local/lib/python3.8/ssl.py", line 1241, in recv_into
    return self.read(nbytes, buffer)
  File "/usr/local/lib/python3.8/ssl.py", line 1099, in read
    return self._sslobj.read(len, buffer)
  File "/home/airflow/.local/lib/python3.8/site-packages/airflow/models/taskinstance.py", line 1634, in signal_handler
    raise AirflowException("Task received SIGTERM signal")
airflow.exceptions.AirflowException: Task received SIGTERM signal
[2024-11-17T08:14:43.129+0000] {taskinstance.py:1400} INFO - Marking task as FAILED. dag_id=model_training_pipeline, task_id=weather_variables_feature_engineering, execution_date=20241117T081407, start_date=20241117T081417, end_date=20241117T081443
[2024-11-17T08:14:43.164+0000] {standard_task_runner.py:104} ERROR - Failed to execute job 279 for task weather_variables_feature_engineering ((psycopg2.errors.ForeignKeyViolation) insert or update on table "task_fail" violates foreign key constraint "task_fail_ti_fkey"
DETAIL:  Key (dag_id, task_id, run_id, map_index)=(model_training_pipeline, weather_variables_feature_engineering, manual__2024-11-17T08:14:07.995917+00:00, -1) is not present in table "task_instance".

[SQL: INSERT INTO task_fail (task_id, dag_id, run_id, map_index, start_date, end_date, duration) VALUES (%(task_id)s, %(dag_id)s, %(run_id)s, %(map_index)s, %(start_date)s, %(end_date)s, %(duration)s) RETURNING task_fail.id]
[parameters: {'task_id': 'weather_variables_feature_engineering', 'dag_id': 'model_training_pipeline', 'run_id': 'manual__2024-11-17T08:14:07.995917+00:00', 'map_index': -1, 'start_date': datetime.datetime(2024, 11, 17, 8, 14, 17, 713987, tzinfo=Timezone('UTC')), 'end_date': datetime.datetime(2024, 11, 17, 8, 14, 43, 128663, tzinfo=Timezone('UTC')), 'duration': 25}]
(Background on this error at: https://sqlalche.me/e/14/gkpj); 147080)
[2024-11-17T08:14:43.217+0000] {process_utils.py:79} INFO - Process psutil.Process(pid=147080, status='terminated', exitcode=1, started='08:14:16') (147080) terminated with exit code 1
