[2024-11-24T09:22:52.635+0000] {logging_mixin.py:151} INFO - Changing /opt/***/logs/dag_id=model_training_pipeline/run_id=manual__2024-11-24T09:22:37.274545+00:00/task_id=train_model permission to 509
[2024-11-24T09:22:52.637+0000] {logging_mixin.py:151} INFO - Failed to change /opt/***/logs/dag_id=model_training_pipeline/run_id=manual__2024-11-24T09:22:37.274545+00:00/task_id=train_model permission to 509: [Errno 1] Operation not permitted: '/opt/***/logs/dag_id=model_training_pipeline/run_id=manual__2024-11-24T09:22:37.274545+00:00/task_id=train_model'
[2024-11-24T09:22:52.692+0000] {logging_mixin.py:151} INFO - Changing /opt/***/logs/dag_id=model_training_pipeline/run_id=manual__2024-11-24T09:22:37.274545+00:00/task_id=train_model permission to 509
[2024-11-24T09:22:52.695+0000] {logging_mixin.py:151} INFO - Failed to change /opt/***/logs/dag_id=model_training_pipeline/run_id=manual__2024-11-24T09:22:37.274545+00:00/task_id=train_model permission to 509: [Errno 1] Operation not permitted: '/opt/***/logs/dag_id=model_training_pipeline/run_id=manual__2024-11-24T09:22:37.274545+00:00/task_id=train_model'
[2024-11-24T09:22:52.736+0000] {taskinstance.py:1159} INFO - Dependencies all met for dep_context=non-requeueable deps ti=<TaskInstance: model_training_pipeline.train_model manual__2024-11-24T09:22:37.274545+00:00 [queued]>
[2024-11-24T09:22:52.752+0000] {taskinstance.py:1159} INFO - Dependencies all met for dep_context=requeueable deps ti=<TaskInstance: model_training_pipeline.train_model manual__2024-11-24T09:22:37.274545+00:00 [queued]>
[2024-11-24T09:22:52.753+0000] {taskinstance.py:1361} INFO - Starting attempt 1 of 2
[2024-11-24T09:22:52.783+0000] {taskinstance.py:1382} INFO - Executing <Task(PythonOperator): train_model> on 2024-11-24 09:22:37.274545+00:00
[2024-11-24T09:22:52.799+0000] {standard_task_runner.py:57} INFO - Started process 769 to run task
[2024-11-24T09:22:52.804+0000] {standard_task_runner.py:84} INFO - Running: ['***', 'tasks', 'run', 'model_training_pipeline', 'train_model', 'manual__2024-11-24T09:22:37.274545+00:00', '--job-id', '22', '--raw', '--subdir', 'DAGS_FOLDER/model_training_pipeline_dag/model_training_dag.py', '--cfg-path', '/tmp/tmpbuhb_l_y']
[2024-11-24T09:22:52.808+0000] {standard_task_runner.py:85} INFO - Job 22: Subtask train_model
[2024-11-24T09:22:52.892+0000] {logging_mixin.py:151} INFO - Changing /opt/***/logs/dag_id=model_training_pipeline/run_id=manual__2024-11-24T09:22:37.274545+00:00/task_id=train_model permission to 509
[2024-11-24T09:22:52.893+0000] {logging_mixin.py:151} INFO - Failed to change /opt/***/logs/dag_id=model_training_pipeline/run_id=manual__2024-11-24T09:22:37.274545+00:00/task_id=train_model permission to 509: [Errno 1] Operation not permitted: '/opt/***/logs/dag_id=model_training_pipeline/run_id=manual__2024-11-24T09:22:37.274545+00:00/task_id=train_model'
[2024-11-24T09:22:52.897+0000] {task_command.py:415} INFO - Running <TaskInstance: model_training_pipeline.train_model manual__2024-11-24T09:22:37.274545+00:00 [running]> on host 71596b931411
[2024-11-24T09:22:53.052+0000] {taskinstance.py:1660} INFO - Exporting env vars: AIRFLOW_CTX_DAG_OWNER='***' AIRFLOW_CTX_DAG_ID='model_training_pipeline' AIRFLOW_CTX_TASK_ID='train_model' AIRFLOW_CTX_EXECUTION_DATE='2024-11-24T09:22:37.274545+00:00' AIRFLOW_CTX_TRY_NUMBER='1' AIRFLOW_CTX_DAG_RUN_ID='manual__2024-11-24T09:22:37.274545+00:00'
[2024-11-24T09:26:22.710+0000] {logging_mixin.py:151} INFO - Data has been normalised
[2024-11-24T09:26:49.567+0000] {logging_mixin.py:151} INFO - Sequences have been saved to /opt/***/dags/sequences/x_sequences_train_7day.npy and /opt/***/dags/sequences/y_sequences_train_7day.npy and 168190 and 168190
[2024-11-24T09:26:49.570+0000] {logging_mixin.py:151} INFO - Error: /opt/***/dags/sequences/x_sequences_train_7day.npy does not exist.
[2024-11-24T09:26:49.573+0000] {logging_mixin.py:151} INFO - Error: /opt/***/dags/sequences/y_sequences_train_7day.npy does not exist.
[2024-11-24T09:26:49.574+0000] {logging_mixin.py:151} INFO - sequences successfully created
[2024-11-24T09:26:49.577+0000] {taskinstance.py:1943} ERROR - Task failed with exception
Traceback (most recent call last):
  File "/home/airflow/.local/lib/python3.8/site-packages/airflow/operators/python.py", line 192, in execute
    return_value = self.execute_callable()
  File "/home/airflow/.local/lib/python3.8/site-packages/airflow/operators/python.py", line 209, in execute_callable
    return self.python_callable(*self.op_args, **self.op_kwargs)
  File "/opt/airflow/dags/model_training_pipeline_dag/train_model.py", line 54, in train_model
    Model.train_model(output_dir='/opt/airflow/dags/sequences', time_steps=30, experiment_id=experiment_id, forecast_horizon=7)
  File "/opt/airflow/dags/modelling/model.py", line 29, in train_model
    x_train = np.load(output_file_x, allow_pickle=True)
  File "/home/airflow/.local/lib/python3.8/site-packages/numpy/lib/npyio.py", line 405, in load
    fid = stack.enter_context(open(os_fspath(file), "rb"))
FileNotFoundError: [Errno 2] No such file or directory: '/opt/airflow/dags/sequences/x_sequences_train_7day.npy'
[2024-11-24T09:26:49.614+0000] {taskinstance.py:1400} INFO - Marking task as UP_FOR_RETRY. dag_id=model_training_pipeline, task_id=train_model, execution_date=20241124T092237, start_date=20241124T092252, end_date=20241124T092649
[2024-11-24T09:26:49.638+0000] {standard_task_runner.py:104} ERROR - Failed to execute job 22 for task train_model ([Errno 2] No such file or directory: '/opt/airflow/dags/sequences/x_sequences_train_7day.npy'; 769)
[2024-11-24T09:26:49.793+0000] {local_task_job_runner.py:228} INFO - Task exited with return code 1
[2024-11-24T09:26:49.943+0000] {taskinstance.py:2784} INFO - 0 downstream tasks scheduled from follow-on schedule check
