[2024-11-20T12:36:07.714+0000] {logging_mixin.py:151} INFO - Changing /opt/***/logs/dag_id=model_training_pipeline/run_id=manual__2024-11-20T12:35:24.464671+00:00/task_id=train_model permission to 509
[2024-11-20T12:36:07.715+0000] {logging_mixin.py:151} INFO - Failed to change /opt/***/logs/dag_id=model_training_pipeline/run_id=manual__2024-11-20T12:35:24.464671+00:00/task_id=train_model permission to 509: [Errno 1] Operation not permitted: '/opt/***/logs/dag_id=model_training_pipeline/run_id=manual__2024-11-20T12:35:24.464671+00:00/task_id=train_model'
[2024-11-20T12:36:07.740+0000] {logging_mixin.py:151} INFO - Changing /opt/***/logs/dag_id=model_training_pipeline/run_id=manual__2024-11-20T12:35:24.464671+00:00/task_id=train_model permission to 509
[2024-11-20T12:36:07.741+0000] {logging_mixin.py:151} INFO - Failed to change /opt/***/logs/dag_id=model_training_pipeline/run_id=manual__2024-11-20T12:35:24.464671+00:00/task_id=train_model permission to 509: [Errno 1] Operation not permitted: '/opt/***/logs/dag_id=model_training_pipeline/run_id=manual__2024-11-20T12:35:24.464671+00:00/task_id=train_model'
[2024-11-20T12:36:07.761+0000] {taskinstance.py:1159} INFO - Dependencies all met for dep_context=non-requeueable deps ti=<TaskInstance: model_training_pipeline.train_model manual__2024-11-20T12:35:24.464671+00:00 [queued]>
[2024-11-20T12:36:07.769+0000] {taskinstance.py:1159} INFO - Dependencies all met for dep_context=requeueable deps ti=<TaskInstance: model_training_pipeline.train_model manual__2024-11-20T12:35:24.464671+00:00 [queued]>
[2024-11-20T12:36:07.769+0000] {taskinstance.py:1361} INFO - Starting attempt 2 of 2
[2024-11-20T12:36:07.781+0000] {taskinstance.py:1382} INFO - Executing <Task(PythonOperator): train_model> on 2024-11-20 12:35:24.464671+00:00
[2024-11-20T12:36:07.792+0000] {standard_task_runner.py:57} INFO - Started process 8855 to run task
[2024-11-20T12:36:07.794+0000] {standard_task_runner.py:84} INFO - Running: ['***', 'tasks', 'run', 'model_training_pipeline', 'train_model', 'manual__2024-11-20T12:35:24.464671+00:00', '--job-id', '329', '--raw', '--subdir', 'DAGS_FOLDER/model_training_pipeline_dag/model_training_dag.py', '--cfg-path', '/tmp/tmppml8mmpf']
[2024-11-20T12:36:07.796+0000] {standard_task_runner.py:85} INFO - Job 329: Subtask train_model
[2024-11-20T12:36:07.836+0000] {logging_mixin.py:151} INFO - Changing /opt/***/logs/dag_id=model_training_pipeline/run_id=manual__2024-11-20T12:35:24.464671+00:00/task_id=train_model permission to 509
[2024-11-20T12:36:07.836+0000] {logging_mixin.py:151} INFO - Failed to change /opt/***/logs/dag_id=model_training_pipeline/run_id=manual__2024-11-20T12:35:24.464671+00:00/task_id=train_model permission to 509: [Errno 1] Operation not permitted: '/opt/***/logs/dag_id=model_training_pipeline/run_id=manual__2024-11-20T12:35:24.464671+00:00/task_id=train_model'
[2024-11-20T12:36:07.838+0000] {task_command.py:415} INFO - Running <TaskInstance: model_training_pipeline.train_model manual__2024-11-20T12:35:24.464671+00:00 [running]> on host 16801ac1f6e4
[2024-11-20T12:36:07.909+0000] {taskinstance.py:1660} INFO - Exporting env vars: AIRFLOW_CTX_DAG_OWNER='***' AIRFLOW_CTX_DAG_ID='model_training_pipeline' AIRFLOW_CTX_TASK_ID='train_model' AIRFLOW_CTX_EXECUTION_DATE='2024-11-20T12:35:24.464671+00:00' AIRFLOW_CTX_TRY_NUMBER='2' AIRFLOW_CTX_DAG_RUN_ID='manual__2024-11-20T12:35:24.464671+00:00'
[2024-11-20T12:36:11.927+0000] {logging_mixin.py:151} INFO - Error retrieving metadata: An error occurred (NoSuchKey) when calling the GetObject operation: The specified key does not exist.
[2024-11-20T12:36:11.929+0000] {logging_mixin.py:151} INFO - {}
[2024-11-20T12:36:11.929+0000] {taskinstance.py:1943} ERROR - Task failed with exception
Traceback (most recent call last):
  File "/home/airflow/.local/lib/python3.8/site-packages/airflow/operators/python.py", line 192, in execute
    return_value = self.execute_callable()
  File "/home/airflow/.local/lib/python3.8/site-packages/airflow/operators/python.py", line 209, in execute_callable
    return self.python_callable(*self.op_args, **self.op_kwargs)
  File "/opt/airflow/dags/model_training_pipeline_dag/train_model.py", line 29, in train_model
    curated_training_data_df = EtlTransforms.json_to_df(data=curated_training_data_json, date_as_index=True)
  File "/opt/airflow/dags/transformation/etl_transforms.py", line 59, in json_to_df
    df = df.set_index('date')
  File "/home/airflow/.local/lib/python3.8/site-packages/pandas/core/frame.py", line 5859, in set_index
    raise KeyError(f"None of {missing} are in the columns")
KeyError: "None of ['date'] are in the columns"
[2024-11-20T12:36:11.945+0000] {taskinstance.py:1400} INFO - Marking task as FAILED. dag_id=model_training_pipeline, task_id=train_model, execution_date=20241120T123524, start_date=20241120T123607, end_date=20241120T123611
[2024-11-20T12:36:11.956+0000] {standard_task_runner.py:104} ERROR - Failed to execute job 329 for task train_model ("None of ['date'] are in the columns"; 8855)
[2024-11-20T12:36:11.980+0000] {local_task_job_runner.py:228} INFO - Task exited with return code 1
[2024-11-20T12:36:11.995+0000] {taskinstance.py:2784} INFO - 0 downstream tasks scheduled from follow-on schedule check
