[2024-11-20T12:35:28.376+0000] {logging_mixin.py:151} INFO - Changing /opt/***/logs/dag_id=model_training_pipeline/run_id=manual__2024-11-20T12:35:24.464671+00:00/task_id=train_model permission to 509
[2024-11-20T12:35:28.377+0000] {logging_mixin.py:151} INFO - Failed to change /opt/***/logs/dag_id=model_training_pipeline/run_id=manual__2024-11-20T12:35:24.464671+00:00/task_id=train_model permission to 509: [Errno 1] Operation not permitted: '/opt/***/logs/dag_id=model_training_pipeline/run_id=manual__2024-11-20T12:35:24.464671+00:00/task_id=train_model'
[2024-11-20T12:35:28.400+0000] {logging_mixin.py:151} INFO - Changing /opt/***/logs/dag_id=model_training_pipeline/run_id=manual__2024-11-20T12:35:24.464671+00:00/task_id=train_model permission to 509
[2024-11-20T12:35:28.401+0000] {logging_mixin.py:151} INFO - Failed to change /opt/***/logs/dag_id=model_training_pipeline/run_id=manual__2024-11-20T12:35:24.464671+00:00/task_id=train_model permission to 509: [Errno 1] Operation not permitted: '/opt/***/logs/dag_id=model_training_pipeline/run_id=manual__2024-11-20T12:35:24.464671+00:00/task_id=train_model'
[2024-11-20T12:35:28.421+0000] {taskinstance.py:1159} INFO - Dependencies all met for dep_context=non-requeueable deps ti=<TaskInstance: model_training_pipeline.train_model manual__2024-11-20T12:35:24.464671+00:00 [queued]>
[2024-11-20T12:35:28.428+0000] {taskinstance.py:1159} INFO - Dependencies all met for dep_context=requeueable deps ti=<TaskInstance: model_training_pipeline.train_model manual__2024-11-20T12:35:24.464671+00:00 [queued]>
[2024-11-20T12:35:28.429+0000] {taskinstance.py:1361} INFO - Starting attempt 1 of 2
[2024-11-20T12:35:28.441+0000] {taskinstance.py:1382} INFO - Executing <Task(PythonOperator): train_model> on 2024-11-20 12:35:24.464671+00:00
[2024-11-20T12:35:28.450+0000] {standard_task_runner.py:57} INFO - Started process 8734 to run task
[2024-11-20T12:35:28.452+0000] {standard_task_runner.py:84} INFO - Running: ['***', 'tasks', 'run', 'model_training_pipeline', 'train_model', 'manual__2024-11-20T12:35:24.464671+00:00', '--job-id', '328', '--raw', '--subdir', 'DAGS_FOLDER/model_training_pipeline_dag/model_training_dag.py', '--cfg-path', '/tmp/tmp8ucozlek']
[2024-11-20T12:35:28.455+0000] {standard_task_runner.py:85} INFO - Job 328: Subtask train_model
[2024-11-20T12:35:28.495+0000] {logging_mixin.py:151} INFO - Changing /opt/***/logs/dag_id=model_training_pipeline/run_id=manual__2024-11-20T12:35:24.464671+00:00/task_id=train_model permission to 509
[2024-11-20T12:35:28.496+0000] {logging_mixin.py:151} INFO - Failed to change /opt/***/logs/dag_id=model_training_pipeline/run_id=manual__2024-11-20T12:35:24.464671+00:00/task_id=train_model permission to 509: [Errno 1] Operation not permitted: '/opt/***/logs/dag_id=model_training_pipeline/run_id=manual__2024-11-20T12:35:24.464671+00:00/task_id=train_model'
[2024-11-20T12:35:28.498+0000] {task_command.py:415} INFO - Running <TaskInstance: model_training_pipeline.train_model manual__2024-11-20T12:35:24.464671+00:00 [running]> on host 16801ac1f6e4
[2024-11-20T12:35:28.568+0000] {taskinstance.py:1660} INFO - Exporting env vars: AIRFLOW_CTX_DAG_OWNER='***' AIRFLOW_CTX_DAG_ID='model_training_pipeline' AIRFLOW_CTX_TASK_ID='train_model' AIRFLOW_CTX_EXECUTION_DATE='2024-11-20T12:35:24.464671+00:00' AIRFLOW_CTX_TRY_NUMBER='1' AIRFLOW_CTX_DAG_RUN_ID='manual__2024-11-20T12:35:24.464671+00:00'
[2024-11-20T12:35:33.004+0000] {logging_mixin.py:151} INFO - Error retrieving metadata: An error occurred (NoSuchKey) when calling the GetObject operation: The specified key does not exist.
[2024-11-20T12:35:33.006+0000] {taskinstance.py:1943} ERROR - Task failed with exception
Traceback (most recent call last):
  File "/home/airflow/.local/lib/python3.8/site-packages/airflow/operators/python.py", line 192, in execute
    return_value = self.execute_callable()
  File "/home/airflow/.local/lib/python3.8/site-packages/airflow/operators/python.py", line 209, in execute_callable
    return self.python_callable(*self.op_args, **self.op_kwargs)
  File "/opt/airflow/dags/model_training_pipeline_dag/train_model.py", line 28, in train_model
    print(curated_training_data_df)
UnboundLocalError: local variable 'curated_training_data_df' referenced before assignment
[2024-11-20T12:35:33.018+0000] {taskinstance.py:1400} INFO - Marking task as UP_FOR_RETRY. dag_id=model_training_pipeline, task_id=train_model, execution_date=20241120T123524, start_date=20241120T123528, end_date=20241120T123533
[2024-11-20T12:35:33.030+0000] {standard_task_runner.py:104} ERROR - Failed to execute job 328 for task train_model (local variable 'curated_training_data_df' referenced before assignment; 8734)
[2024-11-20T12:35:33.045+0000] {local_task_job_runner.py:228} INFO - Task exited with return code 1
[2024-11-20T12:35:33.060+0000] {taskinstance.py:2784} INFO - 0 downstream tasks scheduled from follow-on schedule check
