[2024-11-20T12:18:27.107+0000] {logging_mixin.py:151} INFO - Changing /opt/***/logs/dag_id=model_training_pipeline/run_id=manual__2024-11-20T12:17:38.655112+00:00/task_id=train_model permission to 509
[2024-11-20T12:18:27.108+0000] {logging_mixin.py:151} INFO - Failed to change /opt/***/logs/dag_id=model_training_pipeline/run_id=manual__2024-11-20T12:17:38.655112+00:00/task_id=train_model permission to 509: [Errno 1] Operation not permitted: '/opt/***/logs/dag_id=model_training_pipeline/run_id=manual__2024-11-20T12:17:38.655112+00:00/task_id=train_model'
[2024-11-20T12:18:27.132+0000] {logging_mixin.py:151} INFO - Changing /opt/***/logs/dag_id=model_training_pipeline/run_id=manual__2024-11-20T12:17:38.655112+00:00/task_id=train_model permission to 509
[2024-11-20T12:18:27.132+0000] {logging_mixin.py:151} INFO - Failed to change /opt/***/logs/dag_id=model_training_pipeline/run_id=manual__2024-11-20T12:17:38.655112+00:00/task_id=train_model permission to 509: [Errno 1] Operation not permitted: '/opt/***/logs/dag_id=model_training_pipeline/run_id=manual__2024-11-20T12:17:38.655112+00:00/task_id=train_model'
[2024-11-20T12:18:27.153+0000] {taskinstance.py:1159} INFO - Dependencies all met for dep_context=non-requeueable deps ti=<TaskInstance: model_training_pipeline.train_model manual__2024-11-20T12:17:38.655112+00:00 [queued]>
[2024-11-20T12:18:27.161+0000] {taskinstance.py:1159} INFO - Dependencies all met for dep_context=requeueable deps ti=<TaskInstance: model_training_pipeline.train_model manual__2024-11-20T12:17:38.655112+00:00 [queued]>
[2024-11-20T12:18:27.161+0000] {taskinstance.py:1361} INFO - Starting attempt 2 of 2
[2024-11-20T12:18:27.177+0000] {taskinstance.py:1382} INFO - Executing <Task(PythonOperator): train_model> on 2024-11-20 12:17:38.655112+00:00
[2024-11-20T12:18:27.188+0000] {standard_task_runner.py:57} INFO - Started process 5207 to run task
[2024-11-20T12:18:27.190+0000] {standard_task_runner.py:84} INFO - Running: ['***', 'tasks', 'run', 'model_training_pipeline', 'train_model', 'manual__2024-11-20T12:17:38.655112+00:00', '--job-id', '325', '--raw', '--subdir', 'DAGS_FOLDER/model_training_pipeline_dag/model_training_dag.py', '--cfg-path', '/tmp/tmp9x6h_0xm']
[2024-11-20T12:18:27.192+0000] {standard_task_runner.py:85} INFO - Job 325: Subtask train_model
[2024-11-20T12:18:27.233+0000] {logging_mixin.py:151} INFO - Changing /opt/***/logs/dag_id=model_training_pipeline/run_id=manual__2024-11-20T12:17:38.655112+00:00/task_id=train_model permission to 509
[2024-11-20T12:18:27.233+0000] {logging_mixin.py:151} INFO - Failed to change /opt/***/logs/dag_id=model_training_pipeline/run_id=manual__2024-11-20T12:17:38.655112+00:00/task_id=train_model permission to 509: [Errno 1] Operation not permitted: '/opt/***/logs/dag_id=model_training_pipeline/run_id=manual__2024-11-20T12:17:38.655112+00:00/task_id=train_model'
[2024-11-20T12:18:27.235+0000] {task_command.py:415} INFO - Running <TaskInstance: model_training_pipeline.train_model manual__2024-11-20T12:17:38.655112+00:00 [running]> on host 16801ac1f6e4
[2024-11-20T12:18:27.304+0000] {taskinstance.py:1660} INFO - Exporting env vars: AIRFLOW_CTX_DAG_OWNER='***' AIRFLOW_CTX_DAG_ID='model_training_pipeline' AIRFLOW_CTX_TASK_ID='train_model' AIRFLOW_CTX_EXECUTION_DATE='2024-11-20T12:17:38.655112+00:00' AIRFLOW_CTX_TRY_NUMBER='2' AIRFLOW_CTX_DAG_RUN_ID='manual__2024-11-20T12:17:38.655112+00:00'
[2024-11-20T12:18:29.284+0000] {logging_mixin.py:151} INFO - Error retrieving metadata: An error occurred (NoSuchKey) when calling the GetObject operation: The specified key does not exist.
[2024-11-20T12:18:29.286+0000] {taskinstance.py:1943} ERROR - Task failed with exception
Traceback (most recent call last):
  File "/home/airflow/.local/lib/python3.8/site-packages/airflow/operators/python.py", line 192, in execute
    return_value = self.execute_callable()
  File "/home/airflow/.local/lib/python3.8/site-packages/airflow/operators/python.py", line 209, in execute_callable
    return self.python_callable(*self.op_args, **self.op_kwargs)
  File "/opt/airflow/dags/model_training_pipeline_dag/train_model.py", line 28, in train_model
    curated_training_data_df = EtlTransforms.json_to_df(data=curated_training_data_json, date_as_index=True)
  File "/opt/airflow/dags/transformation/etl_transforms.py", line 59, in json_to_df
    df = df.set_index('date')
  File "/home/airflow/.local/lib/python3.8/site-packages/pandas/core/frame.py", line 5859, in set_index
    raise KeyError(f"None of {missing} are in the columns")
KeyError: "None of ['date'] are in the columns"
[2024-11-20T12:18:29.300+0000] {taskinstance.py:1400} INFO - Marking task as FAILED. dag_id=model_training_pipeline, task_id=train_model, execution_date=20241120T121738, start_date=20241120T121827, end_date=20241120T121829
[2024-11-20T12:18:29.315+0000] {standard_task_runner.py:104} ERROR - Failed to execute job 325 for task train_model ("None of ['date'] are in the columns"; 5207)
[2024-11-20T12:18:29.372+0000] {local_task_job_runner.py:228} INFO - Task exited with return code 1
[2024-11-20T12:18:29.390+0000] {taskinstance.py:2784} INFO - 0 downstream tasks scheduled from follow-on schedule check
